<robot name = "robot">
    <link name="Link0">
        <inertial>
            <origin xyz="0 0 3" rpy="0 0 0"/>
            <mass value="1" />
            <inertia ixx="100" ixy="0" ixz="0" iyy="100" iyz="0" izz="100" />
        </inertial>
        <visual>
            <origin xyz="0 0 3" rpy="0 0 0"/>
            <geometry>
                <box size="0.29355698690111864 0.8212297179889527 0.6435281575214571" />
            </geometry>
            <material name="Green">
                <color rgba="0 1.0 0 1.0"/>
            </material>
        </visual>
        <collision>
            <origin xyz="0 0 3" rpy="0 0 0"/>
            <geometry>
                <box size="0.29355698690111864 0.8212297179889527 0.6435281575214571" />
            </geometry>
        </collision>
    </link>
    <link name="Link1">
        <inertial>
            <origin xyz="0 0.17426093707447063 0" rpy="0 0 0"/>
            <mass value="1" />
            <inertia ixx="100" ixy="0" ixz="0" iyy="100" iyz="0" izz="100" />
        </inertial>
        <visual>
            <origin xyz="0 0.17426093707447063 0" rpy="0 0 0"/>
            <geometry>
                <box size="0.7467841975864491 0.34852187414894126 0.5175184585505641" />
            </geometry>
            <material name="Blue">
                <color rgba="0 0 1.0 1.0"/>
            </material>
        </visual>
        <collision>
            <origin xyz="0 0.17426093707447063 0" rpy="0 0 0"/>
            <geometry>
                <box size="0.7467841975864491 0.34852187414894126 0.5175184585505641" />
            </geometry>
        </collision>
    </link>
    <joint name="Link0_Link1" type="floating">
       <parent link="Link0"/>
       <child  link="Link1"/>
       <origin rpy="0 0 0" xyz="0 0.41061485899447636 3" />
     <axis xyz="0 0 1"/>
       <limit effort="0.0" lower="-3.14159" upper="3.14159" velocity="0.0"/>
    </joint>
    <link name="Link2">
        <inertial>
            <origin xyz="0 0.13325176567035665 0" rpy="0 0 0"/>
            <mass value="1" />
            <inertia ixx="100" ixy="0" ixz="0" iyy="100" iyz="0" izz="100" />
        </inertial>
        <visual>
            <origin xyz="0 0.13325176567035665 0" rpy="0 0 0"/>
            <geometry>
                <box size="1.1405972466583465 0.2665035313407133 0.91051871472213" />
            </geometry>
            <material name="Green">
                <color rgba="0 1.0 0 1.0"/>
            </material>
        </visual>
        <collision>
            <origin xyz="0 0.13325176567035665 0" rpy="0 0 0"/>
            <geometry>
                <box size="1.1405972466583465 0.2665035313407133 0.91051871472213" />
            </geometry>
        </collision>
    </link>
    <joint name="Link1_Link2" type="continuous">
       <parent link="Link1"/>
       <child  link="Link2"/>
       <origin rpy="0 0 0" xyz="0 0.34852187414894126 0" />
     <axis xyz="0 0 1"/>
       <limit effort="0.0" lower="-3.14159" upper="3.14159" velocity="0.0"/>
    </joint>
    <link name="Link3">
        <inertial>
            <origin xyz="0 0.7250481176870277 0" rpy="0 0 0"/>
            <mass value="1" />
            <inertia ixx="100" ixy="0" ixz="0" iyy="100" iyz="0" izz="100" />
        </inertial>
        <visual>
            <origin xyz="0 0.7250481176870277 0" rpy="0 0 0"/>
            <geometry>
                <box size="1.448030915397665 1.4500962353740554 0.6359280973606087" />
            </geometry>
            <material name="Green">
                <color rgba="0 1.0 0 1.0"/>
            </material>
        </visual>
        <collision>
            <origin xyz="0 0.7250481176870277 0" rpy="0 0 0"/>
            <geometry>
                <box size="1.448030915397665 1.4500962353740554 0.6359280973606087" />
            </geometry>
        </collision>
    </link>
    <joint name="Link2_Link3" type="continuous">
       <parent link="Link2"/>
       <child  link="Link3"/>
       <origin rpy="0 0 0" xyz="0 0.2665035313407133 0" />
     <axis xyz="0 1 0"/>
       <limit effort="0.0" lower="-3.14159" upper="3.14159" velocity="0.0"/>
    </joint>
</robot>