<robot name = "robot">
    <link name="Link0">
        <inertial>
            <origin xyz="0 0 3" rpy="0 0 0"/>
            <mass value="1" />
            <inertia ixx="100" ixy="0" ixz="0" iyy="100" iyz="0" izz="100" />
        </inertial>
        <visual>
            <origin xyz="0 0 3" rpy="0 0 0"/>
            <geometry>
                <box size="0.6319210116120428 1.149079975835729 0.9397453062043062" />
            </geometry>
            <material name="Green">
                <color rgba="0 1.0 0 1.0"/>
            </material>
        </visual>
        <collision>
            <origin xyz="0 0 3" rpy="0 0 0"/>
            <geometry>
                <box size="0.6319210116120428 1.149079975835729 0.9397453062043062" />
            </geometry>
        </collision>
    </link>
    <link name="Link1">
        <inertial>
            <origin xyz="0 0.41660295154316673 0" rpy="0 0 0"/>
            <mass value="1" />
            <inertia ixx="100" ixy="0" ixz="0" iyy="100" iyz="0" izz="100" />
        </inertial>
        <visual>
            <origin xyz="0 0.41660295154316673 0" rpy="0 0 0"/>
            <geometry>
                <box size="1.4893215460186353 0.8332059030863335 1.2850340818781842" />
            </geometry>
            <material name="Blue">
                <color rgba="0 0 1.0 1.0"/>
            </material>
        </visual>
        <collision>
            <origin xyz="0 0.41660295154316673 0" rpy="0 0 0"/>
            <geometry>
                <box size="1.4893215460186353 0.8332059030863335 1.2850340818781842" />
            </geometry>
        </collision>
    </link>
    <joint name="Link0_Link1" type="floating">
       <parent link="Link0"/>
       <child  link="Link1"/>
       <origin rpy="0 0 0" xyz="0 0.5745399879178645 3" />
     <axis xyz="0 0 1"/>
       <limit effort="0.0" lower="-3.14159" upper="3.14159" velocity="0.0"/>
    </joint>
    <link name="Link2">
        <inertial>
            <origin xyz="0 0 -0.5623730822624188" rpy="0 0 0"/>
            <mass value="1" />
            <inertia ixx="100" ixy="0" ixz="0" iyy="100" iyz="0" izz="100" />
        </inertial>
        <visual>
            <origin xyz="0 0 -0.5623730822624188" rpy="0 0 0"/>
            <geometry>
                <box size="0.4110962258358813 1.2844549972791668 1.1247461645248376" />
            </geometry>
            <material name="Blue">
                <color rgba="0 0 1.0 1.0"/>
            </material>
        </visual>
        <collision>
            <origin xyz="0 0 -0.5623730822624188" rpy="0 0 0"/>
            <geometry>
                <box size="0.4110962258358813 1.2844549972791668 1.1247461645248376" />
            </geometry>
        </collision>
    </link>
    <joint name="Link1_Link2" type="floating">
       <parent link="Link1"/>
       <child  link="Link2"/>
       <origin rpy="0 0 0" xyz="0 0.41660295154316673 -0.6425170409390921" />
     <axis xyz="0 1 0"/>
       <limit effort="0.0" lower="-3.14159" upper="3.14159" velocity="0.0"/>
    </joint>
    <link name="Link3">
        <inertial>
            <origin xyz="0 0.6636777231879051 0" rpy="0 0 0"/>
            <mass value="1" />
            <inertia ixx="100" ixy="0" ixz="0" iyy="100" iyz="0" izz="100" />
        </inertial>
        <visual>
            <origin xyz="0 0.6636777231879051 0" rpy="0 0 0"/>
            <geometry>
                <box size="0.8373150004272545 1.3273554463758102 0.9926743985924702" />
            </geometry>
            <material name="Blue">
                <color rgba="0 0 1.0 1.0"/>
            </material>
        </visual>
        <collision>
            <origin xyz="0 0.6636777231879051 0" rpy="0 0 0"/>
            <geometry>
                <box size="0.8373150004272545 1.3273554463758102 0.9926743985924702" />
            </geometry>
        </collision>
    </link>
    <joint name="Link2_Link3" type="floating">
       <parent link="Link2"/>
       <child  link="Link3"/>
       <origin rpy="0 0 0" xyz="0 0.6422274986395834 -0.5623730822624188" />
     <axis xyz="0 1 0"/>
       <limit effort="0.0" lower="-3.14159" upper="3.14159" velocity="0.0"/>
    </joint>
</robot>