<robot name = "robot">
    <link name="Link0">
        <inertial>
            <origin xyz="0 0 3" rpy="0 0 0"/>
            <mass value="1" />
            <inertia ixx="100" ixy="0" ixz="0" iyy="100" iyz="0" izz="100" />
        </inertial>
        <visual>
            <origin xyz="0 0 3" rpy="0 0 0"/>
            <geometry>
                <box size="0.21045966563075624 1.15429910145518 0.4816739996802404" />
            </geometry>
            <material name="Green">
                <color rgba="0 1.0 0 1.0"/>
            </material>
        </visual>
        <collision>
            <origin xyz="0 0 3" rpy="0 0 0"/>
            <geometry>
                <box size="0.21045966563075624 1.15429910145518 0.4816739996802404" />
            </geometry>
        </collision>
    </link>
    <link name="Link2">
        <inertial>
            <origin xyz="-0.6418698382261325 0 0" rpy="0 0 0"/>
            <mass value="1" />
            <inertia ixx="100" ixy="0" ixz="0" iyy="100" iyz="0" izz="100" />
        </inertial>
        <visual>
            <origin xyz="-0.6418698382261325 0 0" rpy="0 0 0"/>
            <geometry>
                <box size="1.283739676452265 0.48237497023970044 1.3541478286010717" />
            </geometry>
            <material name="Green">
                <color rgba="0 1.0 0 1.0"/>
            </material>
        </visual>
        <collision>
            <origin xyz="-0.6418698382261325 0 0" rpy="0 0 0"/>
            <geometry>
                <box size="1.283739676452265 0.48237497023970044 1.3541478286010717" />
            </geometry>
        </collision>
    </link>
    <joint name="Link0_Link2" type="floating">
       <parent link="Link0"/>
       <child  link="Link2"/>
       <origin rpy="0 0 0" xyz="-0.10522983281537812 0 3" />
     <axis xyz="0 0 1"/>
       <limit effort="0.0" lower="-3.14159" upper="3.14159" velocity="0.0"/>
    </joint>
    <link name="Link4">
        <inertial>
            <origin xyz="0 0.1827876537439008 0" rpy="0 0 0"/>
            <mass value="1" />
            <inertia ixx="100" ixy="0" ixz="0" iyy="100" iyz="0" izz="100" />
        </inertial>
        <visual>
            <origin xyz="0 0.1827876537439008 0" rpy="0 0 0"/>
            <geometry>
                <box size="0.3564555335944675 0.3655753074878016 1.0517284356331975" />
            </geometry>
            <material name="Blue">
                <color rgba="0 0 1.0 1.0"/>
            </material>
        </visual>
        <collision>
            <origin xyz="0 0.1827876537439008 0" rpy="0 0 0"/>
            <geometry>
                <box size="0.3564555335944675 0.3655753074878016 1.0517284356331975" />
            </geometry>
        </collision>
    </link>
    <joint name="Link0_Link4" type="revolute">
       <parent link="Link0"/>
       <child  link="Link4"/>
       <origin rpy="0 0 0" xyz="0 0.57714955072759 3" />
     <axis xyz="0 0 1"/>
       <limit effort="0.0" lower="-3.14159" upper="3.14159" velocity="0.0"/>
    </joint>
</robot>