<robot name = "robot">
    <link name="Link0">
        <inertial>
            <origin xyz="0 0 3" rpy="0 0 0"/>
            <mass value="1" />
            <inertia ixx="100" ixy="0" ixz="0" iyy="100" iyz="0" izz="100" />
        </inertial>
        <visual>
            <origin xyz="0 0 3" rpy="0 0 0"/>
            <geometry>
                <box size="1.1710884738624558 0.652908282556034 0.02038555104074319" />
            </geometry>
            <material name="Blue">
                <color rgba="0 0 1.0 1.0"/>
            </material>
        </visual>
        <collision>
            <origin xyz="0 0 3" rpy="0 0 0"/>
            <geometry>
                <box size="1.1710884738624558 0.652908282556034 0.02038555104074319" />
            </geometry>
        </collision>
    </link>
    <link name="Link1">
        <inertial>
            <origin xyz="0 -0.02410552510175845 0" rpy="0 0 0"/>
            <mass value="1" />
            <inertia ixx="100" ixy="0" ixz="0" iyy="100" iyz="0" izz="100" />
        </inertial>
        <visual>
            <origin xyz="0 -0.02410552510175845 0" rpy="0 0 0"/>
            <geometry>
                <box size="0.5466149475533325 0.0482110502035169 0.9435179492927062" />
            </geometry>
            <material name="Green">
                <color rgba="0 1.0 0 1.0"/>
            </material>
        </visual>
        <collision>
            <origin xyz="0 -0.02410552510175845 0" rpy="0 0 0"/>
            <geometry>
                <box size="0.5466149475533325 0.0482110502035169 0.9435179492927062" />
            </geometry>
        </collision>
    </link>
    <joint name="Link0_Link1" type="revolute">
       <parent link="Link0"/>
       <child  link="Link1"/>
       <origin rpy="0 0 0" xyz="0 -0.326454141278017 3" />
     <axis xyz="0 1 0"/>
       <limit effort="0.0" lower="-3.14159" upper="3.14159" velocity="0.0"/>
    </joint>
    <link name="Link2">
        <inertial>
            <origin xyz="0 0 -0.7040899605126772" rpy="0 0 0"/>
            <mass value="1" />
            <inertia ixx="100" ixy="0" ixz="0" iyy="100" iyz="0" izz="100" />
        </inertial>
        <visual>
            <origin xyz="0 0 -0.7040899605126772" rpy="0 0 0"/>
            <geometry>
                <box size="1.3916406534495394 0.02392057560899763 1.4081799210253545" />
            </geometry>
            <material name="Green">
                <color rgba="0 1.0 0 1.0"/>
            </material>
        </visual>
        <collision>
            <origin xyz="0 0 -0.7040899605126772" rpy="0 0 0"/>
            <geometry>
                <box size="1.3916406534495394 0.02392057560899763 1.4081799210253545" />
            </geometry>
        </collision>
    </link>
    <joint name="Link1_Link2" type="floating">
       <parent link="Link1"/>
       <child  link="Link2"/>
       <origin rpy="0 0 0" xyz="0 -0.02410552510175845 -0.4717589746463531" />
     <axis xyz="1 0 0"/>
       <limit effort="0.0" lower="-3.14159" upper="3.14159" velocity="0.0"/>
    </joint>
    <link name="Link3">
        <inertial>
            <origin xyz="-0.10259354867974768 0 0" rpy="0 0 0"/>
            <mass value="1" />
            <inertia ixx="100" ixy="0" ixz="0" iyy="100" iyz="0" izz="100" />
        </inertial>
        <visual>
            <origin xyz="-0.10259354867974768 0 0" rpy="0 0 0"/>
            <geometry>
                <box size="0.20518709735949536 0.7317413602875472 1.0944582161762528" />
            </geometry>
            <material name="Blue">
                <color rgba="0 0 1.0 1.0"/>
            </material>
        </visual>
        <collision>
            <origin xyz="-0.10259354867974768 0 0" rpy="0 0 0"/>
            <geometry>
                <box size="0.20518709735949536 0.7317413602875472 1.0944582161762528" />
            </geometry>
        </collision>
    </link>
    <joint name="Link0_Link3" type="floating">
       <parent link="Link0"/>
       <child  link="Link3"/>
       <origin rpy="0 0 0" xyz="-0.5855442369312279 0 3" />
     <axis xyz="0 0 1"/>
       <limit effort="0.0" lower="-3.14159" upper="3.14159" velocity="0.0"/>
    </joint>
    <link name="Link4">
        <inertial>
            <origin xyz="0 -0.45650871595819076 0" rpy="0 0 0"/>
            <mass value="1" />
            <inertia ixx="100" ixy="0" ixz="0" iyy="100" iyz="0" izz="100" />
        </inertial>
        <visual>
            <origin xyz="0 -0.45650871595819076 0" rpy="0 0 0"/>
            <geometry>
                <box size="1.0243661846647232 0.9130174319163815 0.04097336513095384" />
            </geometry>
            <material name="Blue">
                <color rgba="0 0 1.0 1.0"/>
            </material>
        </visual>
        <collision>
            <origin xyz="0 -0.45650871595819076 0" rpy="0 0 0"/>
            <geometry>
                <box size="1.0243661846647232 0.9130174319163815 0.04097336513095384" />
            </geometry>
        </collision>
    </link>
    <joint name="Link1_Link4" type="floating">
       <parent link="Link1"/>
       <child  link="Link4"/>
       <origin rpy="0 0 0" xyz="0 -0.0482110502035169 0" />
     <axis xyz="1 0 0"/>
       <limit effort="0.0" lower="-3.14159" upper="3.14159" velocity="0.0"/>
    </joint>
    <link name="Link5">
        <inertial>
            <origin xyz="0 0 0.48141835224891016" rpy="0 0 0"/>
            <mass value="1" />
            <inertia ixx="100" ixy="0" ixz="0" iyy="100" iyz="0" izz="100" />
        </inertial>
        <visual>
            <origin xyz="0 0 0.48141835224891016" rpy="0 0 0"/>
            <geometry>
                <box size="1.2069729810240881 0.5706008307606534 0.9628367044978203" />
            </geometry>
            <material name="Blue">
                <color rgba="0 0 1.0 1.0"/>
            </material>
        </visual>
        <collision>
            <origin xyz="0 0 0.48141835224891016" rpy="0 0 0"/>
            <geometry>
                <box size="1.2069729810240881 0.5706008307606534 0.9628367044978203" />
            </geometry>
        </collision>
    </link>
    <joint name="Link0_Link5" type="revolute">
       <parent link="Link0"/>
       <child  link="Link5"/>
       <origin rpy="0 0 0" xyz="0 0 3.0101927755203715" />
     <axis xyz="0 1 0"/>
       <limit effort="0.0" lower="-3.14159" upper="3.14159" velocity="0.0"/>
    </joint>
</robot>