<robot name = "robot">
    <link name="Link0">
        <inertial>
            <origin xyz="0 0 3" rpy="0 0 0"/>
            <mass value="1" />
            <inertia ixx="100" ixy="0" ixz="0" iyy="100" iyz="0" izz="100" />
        </inertial>
        <visual>
            <origin xyz="0 0 3" rpy="0 0 0"/>
            <geometry>
                <box size="0.6319210116120428 1.149079975835729 0.9397453062043062" />
            </geometry>
            <material name="Green">
                <color rgba="0 1.0 0 1.0"/>
            </material>
        </visual>
        <collision>
            <origin xyz="0 0 3" rpy="0 0 0"/>
            <geometry>
                <box size="0.6319210116120428 1.149079975835729 0.9397453062043062" />
            </geometry>
        </collision>
    </link>
    <link name="Link1">
        <inertial>
            <origin xyz="0 0.41660295154316673 0" rpy="0 0 0"/>
            <mass value="1" />
            <inertia ixx="100" ixy="0" ixz="0" iyy="100" iyz="0" izz="100" />
        </inertial>
        <visual>
            <origin xyz="0 0.41660295154316673 0" rpy="0 0 0"/>
            <geometry>
                <box size="1.4893215460186353 0.8332059030863335 1.2850340818781842" />
            </geometry>
            <material name="Blue">
                <color rgba="0 0 1.0 1.0"/>
            </material>
        </visual>
        <collision>
            <origin xyz="0 0.41660295154316673 0" rpy="0 0 0"/>
            <geometry>
                <box size="1.4893215460186353 0.8332059030863335 1.2850340818781842" />
            </geometry>
        </collision>
    </link>
    <joint name="Link0_Link1" type="floating">
       <parent link="Link0"/>
       <child  link="Link1"/>
       <origin rpy="0 0 0" xyz="0 0.5745399879178645 3" />
     <axis xyz="0 0 1"/>
       <limit effort="0.0" lower="-3.14159" upper="3.14159" velocity="0.0"/>
    </joint>
    <link name="Link3">
        <inertial>
            <origin xyz="0.5497401376415655 0 0" rpy="0 0 0"/>
            <mass value="1" />
            <inertia ixx="100" ixy="0" ixz="0" iyy="100" iyz="0" izz="100" />
        </inertial>
        <visual>
            <origin xyz="0.5497401376415655 0 0" rpy="0 0 0"/>
            <geometry>
                <box size="1.099480275283131 1.2143169408507446 0.07834111445761566" />
            </geometry>
            <material name="Green">
                <color rgba="0 1.0 0 1.0"/>
            </material>
        </visual>
        <collision>
            <origin xyz="0.5497401376415655 0 0" rpy="0 0 0"/>
            <geometry>
                <box size="1.099480275283131 1.2143169408507446 0.07834111445761566" />
            </geometry>
        </collision>
    </link>
    <joint name="Link0_Link3" type="floating">
       <parent link="Link0"/>
       <child  link="Link3"/>
       <origin rpy="0 0 0" xyz="0.3159605058060214 0 3" />
     <axis xyz="1 0 0"/>
       <limit effort="0.0" lower="-3.14159" upper="3.14159" velocity="0.0"/>
    </joint>
    <link name="Link4">
        <inertial>
            <origin xyz="0.6442149476823227 0 0" rpy="0 0 0"/>
            <mass value="1" />
            <inertia ixx="100" ixy="0" ixz="0" iyy="100" iyz="0" izz="100" />
        </inertial>
        <visual>
            <origin xyz="0.6442149476823227 0 0" rpy="0 0 0"/>
            <geometry>
                <box size="1.2884298953646454 0.3524574544623917 0.35466273360233297" />
            </geometry>
            <material name="Green">
                <color rgba="0 1.0 0 1.0"/>
            </material>
        </visual>
        <collision>
            <origin xyz="0.6442149476823227 0 0" rpy="0 0 0"/>
            <geometry>
                <box size="1.2884298953646454 0.3524574544623917 0.35466273360233297" />
            </geometry>
        </collision>
    </link>
    <joint name="Link3_Link4" type="revolute">
       <parent link="Link3"/>
       <child  link="Link4"/>
       <origin rpy="0 0 0" xyz="1.099480275283131 0 0" />
     <axis xyz="0 0 1"/>
       <limit effort="0.0" lower="-3.14159" upper="3.14159" velocity="0.0"/>
    </joint>
    <link name="Link5">
        <inertial>
            <origin xyz="0 0 0.12022980090534777" rpy="0 0 0"/>
            <mass value="1" />
            <inertia ixx="100" ixy="0" ixz="0" iyy="100" iyz="0" izz="100" />
        </inertial>
        <visual>
            <origin xyz="0 0 0.12022980090534777" rpy="0 0 0"/>
            <geometry>
                <box size="0.9329818329012627 0.6872911969489073 0.24045960181069553" />
            </geometry>
            <material name="Green">
                <color rgba="0 1.0 0 1.0"/>
            </material>
        </visual>
        <collision>
            <origin xyz="0 0 0.12022980090534777" rpy="0 0 0"/>
            <geometry>
                <box size="0.9329818329012627 0.6872911969489073 0.24045960181069553" />
            </geometry>
        </collision>
    </link>
    <joint name="Link3_Link5" type="floating">
       <parent link="Link3"/>
       <child  link="Link5"/>
       <origin rpy="0 0 0" xyz="0.5497401376415655 0 0.03917055722880783" />
     <axis xyz="0 1 0"/>
       <limit effort="0.0" lower="-3.14159" upper="3.14159" velocity="0.0"/>
    </joint>
    <link name="Link7">
        <inertial>
            <origin xyz="0 0.4596270668686627 0" rpy="0 0 0"/>
            <mass value="1" />
            <inertia ixx="100" ixy="0" ixz="0" iyy="100" iyz="0" izz="100" />
        </inertial>
        <visual>
            <origin xyz="0 0.4596270668686627 0" rpy="0 0 0"/>
            <geometry>
                <box size="1.3301822435256692 0.9192541337373255 0.9268702204437773" />
            </geometry>
            <material name="Blue">
                <color rgba="0 0 1.0 1.0"/>
            </material>
        </visual>
        <collision>
            <origin xyz="0 0.4596270668686627 0" rpy="0 0 0"/>
            <geometry>
                <box size="1.3301822435256692 0.9192541337373255 0.9268702204437773" />
            </geometry>
        </collision>
    </link>
    <joint name="Link4_Link7" type="floating">
       <parent link="Link4"/>
       <child  link="Link7"/>
       <origin rpy="0 0 0" xyz="0.6442149476823227 0.17622872723119584 0" />
     <axis xyz="1 0 0"/>
       <limit effort="0.0" lower="-3.14159" upper="3.14159" velocity="0.0"/>
    </joint>
</robot>