<robot name = "robot">
    <link name="Link0">
        <inertial>
            <origin xyz="0 0 3" rpy="0 0 0"/>
            <mass value="1" />
            <inertia ixx="100" ixy="0" ixz="0" iyy="100" iyz="0" izz="100" />
        </inertial>
        <visual>
            <origin xyz="0 0 3" rpy="0 0 0"/>
            <geometry>
                <box size="0.7813449294964325 0.8394989259385207 0.13649489295335487" />
            </geometry>
            <material name="Blue">
                <color rgba="0 0 1.0 1.0"/>
            </material>
        </visual>
        <collision>
            <origin xyz="0 0 3" rpy="0 0 0"/>
            <geometry>
                <box size="0.7813449294964325 0.8394989259385207 0.13649489295335487" />
            </geometry>
        </collision>
    </link>
    <link name="Link1">
        <inertial>
            <origin xyz="0 0 0.11915974311622618" rpy="0 0 0"/>
            <mass value="1" />
            <inertia ixx="100" ixy="0" ixz="0" iyy="100" iyz="0" izz="100" />
        </inertial>
        <visual>
            <origin xyz="0 0 0.11915974311622618" rpy="0 0 0"/>
            <geometry>
                <box size="1.241445699926155 0.3970292563217934 0.23831948623245236" />
            </geometry>
            <material name="Blue">
                <color rgba="0 0 1.0 1.0"/>
            </material>
        </visual>
        <collision>
            <origin xyz="0 0 0.11915974311622618" rpy="0 0 0"/>
            <geometry>
                <box size="1.241445699926155 0.3970292563217934 0.23831948623245236" />
            </geometry>
        </collision>
    </link>
    <joint name="Link0_Link1" type="continuous">
       <parent link="Link0"/>
       <child  link="Link1"/>
       <origin rpy="0 0 0" xyz="0 0 3.0682474464766774" />
     <axis xyz="0 1 0"/>
       <limit effort="0.0" lower="-3.14159" upper="3.14159" velocity="0.0"/>
    </joint>
    <link name="Link2">
        <inertial>
            <origin xyz="0 0.5459341713229381 0" rpy="0 0 0"/>
            <mass value="1" />
            <inertia ixx="100" ixy="0" ixz="0" iyy="100" iyz="0" izz="100" />
        </inertial>
        <visual>
            <origin xyz="0 0.5459341713229381 0" rpy="0 0 0"/>
            <geometry>
                <box size="0.6577023074655513 1.0918683426458762 0.8478779944096444" />
            </geometry>
            <material name="Blue">
                <color rgba="0 0 1.0 1.0"/>
            </material>
        </visual>
        <collision>
            <origin xyz="0 0.5459341713229381 0" rpy="0 0 0"/>
            <geometry>
                <box size="0.6577023074655513 1.0918683426458762 0.8478779944096444" />
            </geometry>
        </collision>
    </link>
    <joint name="Link1_Link2" type="floating">
       <parent link="Link1"/>
       <child  link="Link2"/>
       <origin rpy="0 0 0" xyz="0 0.1985146281608967 0.11915974311622618" />
     <axis xyz="0 1 0"/>
       <limit effort="0.0" lower="-3.14159" upper="3.14159" velocity="0.0"/>
    </joint>
    <link name="Link3">
        <inertial>
            <origin xyz="0 0 0.037319952473596124" rpy="0 0 0"/>
            <mass value="1" />
            <inertia ixx="100" ixy="0" ixz="0" iyy="100" iyz="0" izz="100" />
        </inertial>
        <visual>
            <origin xyz="0 0 0.037319952473596124" rpy="0 0 0"/>
            <geometry>
                <box size="1.009969759067683 1.1773645992577748 0.07463990494719225" />
            </geometry>
            <material name="Green">
                <color rgba="0 1.0 0 1.0"/>
            </material>
        </visual>
        <collision>
            <origin xyz="0 0 0.037319952473596124" rpy="0 0 0"/>
            <geometry>
                <box size="1.009969759067683 1.1773645992577748 0.07463990494719225" />
            </geometry>
        </collision>
    </link>
    <joint name="Link1_Link3" type="continuous">
       <parent link="Link1"/>
       <child  link="Link3"/>
       <origin rpy="0 0 0" xyz="0 0 0.23831948623245236" />
     <axis xyz="0 0 1"/>
       <limit effort="0.0" lower="-3.14159" upper="3.14159" velocity="0.0"/>
    </joint>
    <link name="Link4">
        <inertial>
            <origin xyz="0 0.5900774224767168 0" rpy="0 0 0"/>
            <mass value="1" />
            <inertia ixx="100" ixy="0" ixz="0" iyy="100" iyz="0" izz="100" />
        </inertial>
        <visual>
            <origin xyz="0 0.5900774224767168 0" rpy="0 0 0"/>
            <geometry>
                <box size="1.395241554983897 1.1801548449534336 1.3126910879676443" />
            </geometry>
            <material name="Green">
                <color rgba="0 1.0 0 1.0"/>
            </material>
        </visual>
        <collision>
            <origin xyz="0 0.5900774224767168 0" rpy="0 0 0"/>
            <geometry>
                <box size="1.395241554983897 1.1801548449534336 1.3126910879676443" />
            </geometry>
        </collision>
    </link>
    <joint name="Link3_Link4" type="floating">
       <parent link="Link3"/>
       <child  link="Link4"/>
       <origin rpy="0 0 0" xyz="0 0.5886822996288874 0.037319952473596124" />
     <axis xyz="0 1 0"/>
       <limit effort="0.0" lower="-3.14159" upper="3.14159" velocity="0.0"/>
    </joint>
</robot>