<robot name = "robot">
    <link name="Link0">
        <inertial>
            <origin xyz="0 0 3" rpy="0 0 0"/>
            <mass value="1" />
            <inertia ixx="100" ixy="0" ixz="0" iyy="100" iyz="0" izz="100" />
        </inertial>
        <visual>
            <origin xyz="0 0 3" rpy="0 0 0"/>
            <geometry>
                <box size="0.0780873648373584 0.2648626873257333 0.05255480051430195" />
            </geometry>
            <material name="Blue">
                <color rgba="0 0 1.0 1.0"/>
            </material>
        </visual>
        <collision>
            <origin xyz="0 0 3" rpy="0 0 0"/>
            <geometry>
                <box size="0.0780873648373584 0.2648626873257333 0.05255480051430195" />
            </geometry>
        </collision>
    </link>
    <link name="Link1">
        <inertial>
            <origin xyz="0 0 0.4940392220996059" rpy="0 0 0"/>
            <mass value="1" />
            <inertia ixx="100" ixy="0" ixz="0" iyy="100" iyz="0" izz="100" />
        </inertial>
        <visual>
            <origin xyz="0 0 0.4940392220996059" rpy="0 0 0"/>
            <geometry>
                <box size="0.7507176755540839 0.44224062545908005 0.9880784441992118" />
            </geometry>
            <material name="Green">
                <color rgba="0 1.0 0 1.0"/>
            </material>
        </visual>
        <collision>
            <origin xyz="0 0 0.4940392220996059" rpy="0 0 0"/>
            <geometry>
                <box size="0.7507176755540839 0.44224062545908005 0.9880784441992118" />
            </geometry>
        </collision>
    </link>
    <joint name="Link0_Link1" type="continuous">
       <parent link="Link0"/>
       <child  link="Link1"/>
       <origin rpy="0 0 0" xyz="0 0 3.026277400257151" />
     <axis xyz="0 0 1"/>
       <limit effort="0.0" lower="-3.14159" upper="3.14159" velocity="0.0"/>
    </joint>
    <link name="Link2">
        <inertial>
            <origin xyz="0 0.10320789999082189 0" rpy="0 0 0"/>
            <mass value="1" />
            <inertia ixx="100" ixy="0" ixz="0" iyy="100" iyz="0" izz="100" />
        </inertial>
        <visual>
            <origin xyz="0 0.10320789999082189 0" rpy="0 0 0"/>
            <geometry>
                <box size="1.243782038999165 0.20641579998164378 0.8997677707254119" />
            </geometry>
            <material name="Green">
                <color rgba="0 1.0 0 1.0"/>
            </material>
        </visual>
        <collision>
            <origin xyz="0 0.10320789999082189 0" rpy="0 0 0"/>
            <geometry>
                <box size="1.243782038999165 0.20641579998164378 0.8997677707254119" />
            </geometry>
        </collision>
    </link>
    <joint name="Link1_Link2" type="continuous">
       <parent link="Link1"/>
       <child  link="Link2"/>
       <origin rpy="0 0 0" xyz="0 0.22112031272954003 0.4940392220996059" />
     <axis xyz="0 0 1"/>
       <limit effort="0.0" lower="-3.14159" upper="3.14159" velocity="0.0"/>
    </joint>
    <link name="Link3">
        <inertial>
            <origin xyz="0 0 0.052548047426642625" rpy="0 0 0"/>
            <mass value="1" />
            <inertia ixx="100" ixy="0" ixz="0" iyy="100" iyz="0" izz="100" />
        </inertial>
        <visual>
            <origin xyz="0 0 0.052548047426642625" rpy="0 0 0"/>
            <geometry>
                <box size="0.3244373670392574 0.06077317415633621 0.10509609485328525" />
            </geometry>
            <material name="Green">
                <color rgba="0 1.0 0 1.0"/>
            </material>
        </visual>
        <collision>
            <origin xyz="0 0 0.052548047426642625" rpy="0 0 0"/>
            <geometry>
                <box size="0.3244373670392574 0.06077317415633621 0.10509609485328525" />
            </geometry>
        </collision>
    </link>
    <joint name="Link0_Link3" type="revolute">
       <parent link="Link0"/>
       <child  link="Link3"/>
       <origin rpy="0 0 0" xyz="0 0 3.026277400257151" />
     <axis xyz="0 1 0"/>
       <limit effort="0.0" lower="-3.14159" upper="3.14159" velocity="0.0"/>
    </joint>
    <link name="Link4">
        <inertial>
            <origin xyz="0 0.5011977967158306 0" rpy="0 0 0"/>
            <mass value="1" />
            <inertia ixx="100" ixy="0" ixz="0" iyy="100" iyz="0" izz="100" />
        </inertial>
        <visual>
            <origin xyz="0 0.5011977967158306 0" rpy="0 0 0"/>
            <geometry>
                <box size="0.20122699773641095 1.0023955934316613 0.3859922158194473" />
            </geometry>
            <material name="Blue">
                <color rgba="0 0 1.0 1.0"/>
            </material>
        </visual>
        <collision>
            <origin xyz="0 0.5011977967158306 0" rpy="0 0 0"/>
            <geometry>
                <box size="0.20122699773641095 1.0023955934316613 0.3859922158194473" />
            </geometry>
        </collision>
    </link>
    <joint name="Link3_Link4" type="revolute">
       <parent link="Link3"/>
       <child  link="Link4"/>
       <origin rpy="0 0 0" xyz="0 0.030386587078168104 0.052548047426642625" />
     <axis xyz="0 1 0"/>
       <limit effort="0.0" lower="-3.14159" upper="3.14159" velocity="0.0"/>
    </joint>
    <link name="Link5">
        <inertial>
            <origin xyz="0 0 -0.27904354254588604" rpy="0 0 0"/>
            <mass value="1" />
            <inertia ixx="100" ixy="0" ixz="0" iyy="100" iyz="0" izz="100" />
        </inertial>
        <visual>
            <origin xyz="0 0 -0.27904354254588604" rpy="0 0 0"/>
            <geometry>
                <box size="1.040582906148517 1.2572741750136829 0.5580870850917721" />
            </geometry>
            <material name="Blue">
                <color rgba="0 0 1.0 1.0"/>
            </material>
        </visual>
        <collision>
            <origin xyz="0 0 -0.27904354254588604" rpy="0 0 0"/>
            <geometry>
                <box size="1.040582906148517 1.2572741750136829 0.5580870850917721" />
            </geometry>
        </collision>
    </link>
    <joint name="Link0_Link5" type="floating">
       <parent link="Link0"/>
       <child  link="Link5"/>
       <origin rpy="0 0 0" xyz="0 0 2.973722599742849" />
     <axis xyz="0 1 0"/>
       <limit effort="0.0" lower="-3.14159" upper="3.14159" velocity="0.0"/>
    </joint>
</robot>