<robot name = "robot">
    <link name="Link0">
        <inertial>
            <origin xyz="0 0 3" rpy="0 0 0"/>
            <mass value="1" />
            <inertia ixx="100" ixy="0" ixz="0" iyy="100" iyz="0" izz="100" />
        </inertial>
        <visual>
            <origin xyz="0 0 3" rpy="0 0 0"/>
            <geometry>
                <box size="1.0248022157754137 0.045493695573219195 0.2645276788496836" />
            </geometry>
            <material name="Green">
                <color rgba="0 1.0 0 1.0"/>
            </material>
        </visual>
        <collision>
            <origin xyz="0 0 3" rpy="0 0 0"/>
            <geometry>
                <box size="1.0248022157754137 0.045493695573219195 0.2645276788496836" />
            </geometry>
        </collision>
    </link>
    <link name="Link1">
        <inertial>
            <origin xyz="0 0 -0.2947778883452147" rpy="0 0 0"/>
            <mass value="1" />
            <inertia ixx="100" ixy="0" ixz="0" iyy="100" iyz="0" izz="100" />
        </inertial>
        <visual>
            <origin xyz="0 0 -0.2947778883452147" rpy="0 0 0"/>
            <geometry>
                <box size="0.21572105849256645 0.30295140248754354 0.5895557766904294" />
            </geometry>
            <material name="Green">
                <color rgba="0 1.0 0 1.0"/>
            </material>
        </visual>
        <collision>
            <origin xyz="0 0 -0.2947778883452147" rpy="0 0 0"/>
            <geometry>
                <box size="0.21572105849256645 0.30295140248754354 0.5895557766904294" />
            </geometry>
        </collision>
    </link>
    <joint name="Link0_Link1" type="continuous">
       <parent link="Link0"/>
       <child  link="Link1"/>
       <origin rpy="0 0 0" xyz="0 0 2.8677361605751583" />
     <axis xyz="0 0 1"/>
       <limit effort="0.0" lower="-3.14159" upper="3.14159" velocity="0.0"/>
    </joint>
    <link name="Link2">
        <inertial>
            <origin xyz="-0.6435924147999734 0 0" rpy="0 0 0"/>
            <mass value="1" />
            <inertia ixx="100" ixy="0" ixz="0" iyy="100" iyz="0" izz="100" />
        </inertial>
        <visual>
            <origin xyz="-0.6435924147999734 0 0" rpy="0 0 0"/>
            <geometry>
                <box size="1.2871848295999468 0.19338138330730292 1.2536124545706828" />
            </geometry>
            <material name="Blue">
                <color rgba="0 0 1.0 1.0"/>
            </material>
        </visual>
        <collision>
            <origin xyz="-0.6435924147999734 0 0" rpy="0 0 0"/>
            <geometry>
                <box size="1.2871848295999468 0.19338138330730292 1.2536124545706828" />
            </geometry>
        </collision>
    </link>
    <joint name="Link0_Link2" type="floating">
       <parent link="Link0"/>
       <child  link="Link2"/>
       <origin rpy="0 0 0" xyz="-0.5124011078877069 0 3" />
     <axis xyz="1 0 0"/>
       <limit effort="0.0" lower="-3.14159" upper="3.14159" velocity="0.0"/>
    </joint>
    <link name="Link3">
        <inertial>
            <origin xyz="0 0 0.3371305881454719" rpy="0 0 0"/>
            <mass value="1" />
            <inertia ixx="100" ixy="0" ixz="0" iyy="100" iyz="0" izz="100" />
        </inertial>
        <visual>
            <origin xyz="0 0 0.3371305881454719" rpy="0 0 0"/>
            <geometry>
                <box size="0.6361416029970375 0.7159292366859882 0.6742611762909438" />
            </geometry>
            <material name="Blue">
                <color rgba="0 0 1.0 1.0"/>
            </material>
        </visual>
        <collision>
            <origin xyz="0 0 0.3371305881454719" rpy="0 0 0"/>
            <geometry>
                <box size="0.6361416029970375 0.7159292366859882 0.6742611762909438" />
            </geometry>
        </collision>
    </link>
    <joint name="Link2_Link3" type="continuous">
       <parent link="Link2"/>
       <child  link="Link3"/>
       <origin rpy="0 0 0" xyz="-0.6435924147999734 0 0.6268062272853414" />
     <axis xyz="0 0 1"/>
       <limit effort="0.0" lower="-3.14159" upper="3.14159" velocity="0.0"/>
    </joint>
    <link name="Link4">
        <inertial>
            <origin xyz="0.4191751646225286 0 0" rpy="0 0 0"/>
            <mass value="1" />
            <inertia ixx="100" ixy="0" ixz="0" iyy="100" iyz="0" izz="100" />
        </inertial>
        <visual>
            <origin xyz="0.4191751646225286 0 0" rpy="0 0 0"/>
            <geometry>
                <box size="0.8383503292450571 1.0878199139942557 1.285583702219613" />
            </geometry>
            <material name="Blue">
                <color rgba="0 0 1.0 1.0"/>
            </material>
        </visual>
        <collision>
            <origin xyz="0.4191751646225286 0 0" rpy="0 0 0"/>
            <geometry>
                <box size="0.8383503292450571 1.0878199139942557 1.285583702219613" />
            </geometry>
        </collision>
    </link>
    <joint name="Link1_Link4" type="floating">
       <parent link="Link1"/>
       <child  link="Link4"/>
       <origin rpy="0 0 0" xyz="0.10786052924628323 0 -0.2947778883452147" />
     <axis xyz="0 1 0"/>
       <limit effort="0.0" lower="-3.14159" upper="3.14159" velocity="0.0"/>
    </joint>
    <link name="Link5">
        <inertial>
            <origin xyz="0 0.04309732974641367 0" rpy="0 0 0"/>
            <mass value="1" />
            <inertia ixx="100" ixy="0" ixz="0" iyy="100" iyz="0" izz="100" />
        </inertial>
        <visual>
            <origin xyz="0 0.04309732974641367 0" rpy="0 0 0"/>
            <geometry>
                <box size="1.1408326536102067 0.08619465949282734 0.889609068664676" />
            </geometry>
            <material name="Green">
                <color rgba="0 1.0 0 1.0"/>
            </material>
        </visual>
        <collision>
            <origin xyz="0 0.04309732974641367 0" rpy="0 0 0"/>
            <geometry>
                <box size="1.1408326536102067 0.08619465949282734 0.889609068664676" />
            </geometry>
        </collision>
    </link>
    <joint name="Link0_Link5" type="floating">
       <parent link="Link0"/>
       <child  link="Link5"/>
       <origin rpy="0 0 0" xyz="0 0.022746847786609597 3" />
     <axis xyz="0 0 1"/>
       <limit effort="0.0" lower="-3.14159" upper="3.14159" velocity="0.0"/>
    </joint>
    <link name="Link6">
        <inertial>
            <origin xyz="0.7003395421848664 0 0" rpy="0 0 0"/>
            <mass value="1" />
            <inertia ixx="100" ixy="0" ixz="0" iyy="100" iyz="0" izz="100" />
        </inertial>
        <visual>
            <origin xyz="0.7003395421848664 0 0" rpy="0 0 0"/>
            <geometry>
                <box size="1.4006790843697328 1.2318370185414587 1.3382687280732815" />
            </geometry>
            <material name="Blue">
                <color rgba="0 0 1.0 1.0"/>
            </material>
        </visual>
        <collision>
            <origin xyz="0.7003395421848664 0 0" rpy="0 0 0"/>
            <geometry>
                <box size="1.4006790843697328 1.2318370185414587 1.3382687280732815" />
            </geometry>
        </collision>
    </link>
    <joint name="Link3_Link6" type="continuous">
       <parent link="Link3"/>
       <child  link="Link6"/>
       <origin rpy="0 0 0" xyz="0.31807080149851874 0 0.3371305881454719" />
     <axis xyz="0 1 0"/>
       <limit effort="0.0" lower="-3.14159" upper="3.14159" velocity="0.0"/>
    </joint>
</robot>