<robot name = "robot">
    <link name="Link0">
        <inertial>
            <origin xyz="0 0 3" rpy="0 0 0"/>
            <mass value="1" />
            <inertia ixx="100" ixy="0" ixz="0" iyy="100" iyz="0" izz="100" />
        </inertial>
        <visual>
            <origin xyz="0 0 3" rpy="0 0 0"/>
            <geometry>
                <box size="0.29355698690111864 0.8212297179889527 0.6435281575214571" />
            </geometry>
            <material name="Green">
                <color rgba="0 1.0 0 1.0"/>
            </material>
        </visual>
        <collision>
            <origin xyz="0 0 3" rpy="0 0 0"/>
            <geometry>
                <box size="0.29355698690111864 0.8212297179889527 0.6435281575214571" />
            </geometry>
        </collision>
    </link>
    <link name="Link1">
        <inertial>
            <origin xyz="0 0.17426093707447063 0" rpy="0 0 0"/>
            <mass value="1" />
            <inertia ixx="100" ixy="0" ixz="0" iyy="100" iyz="0" izz="100" />
        </inertial>
        <visual>
            <origin xyz="0 0.17426093707447063 0" rpy="0 0 0"/>
            <geometry>
                <box size="0.7467841975864491 0.34852187414894126 0.5175184585505641" />
            </geometry>
            <material name="Blue">
                <color rgba="0 0 1.0 1.0"/>
            </material>
        </visual>
        <collision>
            <origin xyz="0 0.17426093707447063 0" rpy="0 0 0"/>
            <geometry>
                <box size="0.7467841975864491 0.34852187414894126 0.5175184585505641" />
            </geometry>
        </collision>
    </link>
    <joint name="Link0_Link1" type="floating">
       <parent link="Link0"/>
       <child  link="Link1"/>
       <origin rpy="0 0 0" xyz="0 0.41061485899447636 3" />
     <axis xyz="0 0 1"/>
       <limit effort="0.0" lower="-3.14159" upper="3.14159" velocity="0.0"/>
    </joint>
    <link name="Link2">
        <inertial>
            <origin xyz="0 0.13325176567035665 0" rpy="0 0 0"/>
            <mass value="1" />
            <inertia ixx="100" ixy="0" ixz="0" iyy="100" iyz="0" izz="100" />
        </inertial>
        <visual>
            <origin xyz="0 0.13325176567035665 0" rpy="0 0 0"/>
            <geometry>
                <box size="1.1405972466583465 0.2665035313407133 0.91051871472213" />
            </geometry>
            <material name="Green">
                <color rgba="0 1.0 0 1.0"/>
            </material>
        </visual>
        <collision>
            <origin xyz="0 0.13325176567035665 0" rpy="0 0 0"/>
            <geometry>
                <box size="1.1405972466583465 0.2665035313407133 0.91051871472213" />
            </geometry>
        </collision>
    </link>
    <joint name="Link1_Link2" type="continuous">
       <parent link="Link1"/>
       <child  link="Link2"/>
       <origin rpy="0 0 0" xyz="0 0.34852187414894126 0" />
     <axis xyz="0 0 1"/>
       <limit effort="0.0" lower="-3.14159" upper="3.14159" velocity="0.0"/>
    </joint>
    <link name="Link3">
        <inertial>
            <origin xyz="-0.03690309637652103 0 0" rpy="0 0 0"/>
            <mass value="1" />
            <inertia ixx="100" ixy="0" ixz="0" iyy="100" iyz="0" izz="100" />
        </inertial>
        <visual>
            <origin xyz="-0.03690309637652103 0 0" rpy="0 0 0"/>
            <geometry>
                <box size="0.07380619275304207 1.180913715740367 0.6752178527976301" />
            </geometry>
            <material name="Green">
                <color rgba="0 1.0 0 1.0"/>
            </material>
        </visual>
        <collision>
            <origin xyz="-0.03690309637652103 0 0" rpy="0 0 0"/>
            <geometry>
                <box size="0.07380619275304207 1.180913715740367 0.6752178527976301" />
            </geometry>
        </collision>
    </link>
    <joint name="Link0_Link3" type="floating">
       <parent link="Link0"/>
       <child  link="Link3"/>
       <origin rpy="0 0 0" xyz="-0.14677849345055932 0 3" />
     <axis xyz="1 0 0"/>
       <limit effort="0.0" lower="-3.14159" upper="3.14159" velocity="0.0"/>
    </joint>
    <link name="Link4">
        <inertial>
            <origin xyz="-0.5015940330875617 0 0" rpy="0 0 0"/>
            <mass value="1" />
            <inertia ixx="100" ixy="0" ixz="0" iyy="100" iyz="0" izz="100" />
        </inertial>
        <visual>
            <origin xyz="-0.5015940330875617 0 0" rpy="0 0 0"/>
            <geometry>
                <box size="1.0031880661751233 0.23646182718382425 1.4710476507679882" />
            </geometry>
            <material name="Green">
                <color rgba="0 1.0 0 1.0"/>
            </material>
        </visual>
        <collision>
            <origin xyz="-0.5015940330875617 0 0" rpy="0 0 0"/>
            <geometry>
                <box size="1.0031880661751233 0.23646182718382425 1.4710476507679882" />
            </geometry>
        </collision>
    </link>
    <joint name="Link1_Link4" type="floating">
       <parent link="Link1"/>
       <child  link="Link4"/>
       <origin rpy="0 0 0" xyz="-0.37339209879322455 0.17426093707447063 0" />
     <axis xyz="1 0 0"/>
       <limit effort="0.0" lower="-3.14159" upper="3.14159" velocity="0.0"/>
    </joint>
    <link name="Link7">
        <inertial>
            <origin xyz="0 -0.3618979267601628 0" rpy="0 0 0"/>
            <mass value="1" />
            <inertia ixx="100" ixy="0" ixz="0" iyy="100" iyz="0" izz="100" />
        </inertial>
        <visual>
            <origin xyz="0 -0.3618979267601628 0" rpy="0 0 0"/>
            <geometry>
                <box size="0.040178960757198456 0.7237958535203256 0.8806333747503446" />
            </geometry>
            <material name="Green">
                <color rgba="0 1.0 0 1.0"/>
            </material>
        </visual>
        <collision>
            <origin xyz="0 -0.3618979267601628 0" rpy="0 0 0"/>
            <geometry>
                <box size="0.040178960757198456 0.7237958535203256 0.8806333747503446" />
            </geometry>
        </collision>
    </link>
    <joint name="Link4_Link7" type="continuous">
       <parent link="Link4"/>
       <child  link="Link7"/>
       <origin rpy="0 0 0" xyz="-0.5015940330875617 -0.11823091359191212 0" />
     <axis xyz="1 0 0"/>
       <limit effort="0.0" lower="-3.14159" upper="3.14159" velocity="0.0"/>
    </joint>
    <link name="Link8">
        <inertial>
            <origin xyz="0 0 0.6711368090461073" rpy="0 0 0"/>
            <mass value="1" />
            <inertia ixx="100" ixy="0" ixz="0" iyy="100" iyz="0" izz="100" />
        </inertial>
        <visual>
            <origin xyz="0 0 0.6711368090461073" rpy="0 0 0"/>
            <geometry>
                <box size="1.2268897943489951 0.10204832405437231 1.3422736180922146" />
            </geometry>
            <material name="Blue">
                <color rgba="0 0 1.0 1.0"/>
            </material>
        </visual>
        <collision>
            <origin xyz="0 0 0.6711368090461073" rpy="0 0 0"/>
            <geometry>
                <box size="1.2268897943489951 0.10204832405437231 1.3422736180922146" />
            </geometry>
        </collision>
    </link>
    <joint name="Link4_Link8" type="continuous">
       <parent link="Link4"/>
       <child  link="Link8"/>
       <origin rpy="0 0 0" xyz="-0.5015940330875617 0 0.7355238253839941" />
     <axis xyz="0 0 1"/>
       <limit effort="0.0" lower="-3.14159" upper="3.14159" velocity="0.0"/>
    </joint>
</robot>