<robot name = "robot">
    <link name="Link0">
        <inertial>
            <origin xyz="0 0 3" rpy="0 0 0"/>
            <mass value="1" />
            <inertia ixx="100" ixy="0" ixz="0" iyy="100" iyz="0" izz="100" />
        </inertial>
        <visual>
            <origin xyz="0 0 3" rpy="0 0 0"/>
            <geometry>
                <box size="0.5892587456048781 0.9678709277911421 1.102550748417383" />
            </geometry>
            <material name="Green">
                <color rgba="0 1.0 0 1.0"/>
            </material>
        </visual>
        <collision>
            <origin xyz="0 0 3" rpy="0 0 0"/>
            <geometry>
                <box size="0.5892587456048781 0.9678709277911421 1.102550748417383" />
            </geometry>
        </collision>
    </link>
    <link name="Link1">
        <inertial>
            <origin xyz="0 0 -0.6603063014267999" rpy="0 0 0"/>
            <mass value="1" />
            <inertia ixx="100" ixy="0" ixz="0" iyy="100" iyz="0" izz="100" />
        </inertial>
        <visual>
            <origin xyz="0 0 -0.6603063014267999" rpy="0 0 0"/>
            <geometry>
                <box size="0.2387195082361277 0.7979895488258162 1.3206126028535998" />
            </geometry>
            <material name="Green">
                <color rgba="0 1.0 0 1.0"/>
            </material>
        </visual>
        <collision>
            <origin xyz="0 0 -0.6603063014267999" rpy="0 0 0"/>
            <geometry>
                <box size="0.2387195082361277 0.7979895488258162 1.3206126028535998" />
            </geometry>
        </collision>
    </link>
    <joint name="Link0_Link1" type="floating">
       <parent link="Link0"/>
       <child  link="Link1"/>
       <origin rpy="0 0 0" xyz="0 0 2.4487246257913085" />
     <axis xyz="1 0 0"/>
       <limit effort="0.0" lower="-3.14159" upper="3.14159" velocity="0.0"/>
    </joint>
    <link name="Link2">
        <inertial>
            <origin xyz="-0.2980860697160189 0 0" rpy="0 0 0"/>
            <mass value="1" />
            <inertia ixx="100" ixy="0" ixz="0" iyy="100" iyz="0" izz="100" />
        </inertial>
        <visual>
            <origin xyz="-0.2980860697160189 0 0" rpy="0 0 0"/>
            <geometry>
                <box size="0.5961721394320378 1.2292183741672993 0.11109368780118345" />
            </geometry>
            <material name="Blue">
                <color rgba="0 0 1.0 1.0"/>
            </material>
        </visual>
        <collision>
            <origin xyz="-0.2980860697160189 0 0" rpy="0 0 0"/>
            <geometry>
                <box size="0.5961721394320378 1.2292183741672993 0.11109368780118345" />
            </geometry>
        </collision>
    </link>
    <joint name="Link0_Link2" type="continuous">
       <parent link="Link0"/>
       <child  link="Link2"/>
       <origin rpy="0 0 0" xyz="-0.29462937280243906 0 3" />
     <axis xyz="0 1 0"/>
       <limit effort="0.0" lower="-3.14159" upper="3.14159" velocity="0.0"/>
    </joint>
</robot>